Workbook

Sheet Resumen Ejecutivo
A1: LOCALMARKET PWA - INFORME EJECUTIVO DE METRICAS DE SOFTWARE
A2: Estimacion de Tamano Funcional mediante Analisis de Puntos de Funcion (IFPUG / Modelo de Albrecht)
A4: TABLAS DE BD ANALIZADAS | C4: TOTAL TRANSACCIONES | E4: TOTAL PFNA (NO AJUSTADOS) | F4: FACTOR DE AJUSTE (CAF) | G4: TOTAL PFA (AJUSTADOS)
A5: 13 Tablas | C5: 100 Funciones | E5: ='Consolidado PFNA'!H18 | F5: ='PF Ajustados'!B26 | G5: ='PF Ajustados'!B27
A6: Modelo Relacional Completo | C6: EI, EO, EQ, ILF y EIF | E6: Puntos Funcionales Brutos | F6: 14 Factores de Albrecht | G6: Tamano Funcional Final
A8: 1. FICHA TECNICA DEL SISTEMA ANALIZADO
A9: Sistema / Software | B9: LocalMarket - Plataforma Web Progresiva (PWA) de Comercio Local
A10: Arquitectura del Sistema | B10: Node.js, Express, PostgreSQL 18, Service Workers PWA, CSS/Tailwind UI
A11: Ambito de Metricas | B11: 13 Tablas Principales de la Base de Datos Relacional y sus Interacciones
A12: Metodologia Aplicada | B12: Metricas de Puntos de Funcion (IFPUG FPA Release 4.3 / Modelo de Ajuste de Albrecht)
A13: Documento Base de Referencia | B13: Plantilla oficial estandarizada 'PuntosDeFuncion.DOC'
A14: Objetivo del Estudio | B14: Cuantificar el tamano funcional del software, evaluar la complejidad tecnica y estimar el esfuerzo de desarrollo
A16: 2. DISTRIBUCION DEL TAMANO FUNCIONAL POR TIPO DE COMPONENTE
A17: Tipo de Componente Funcional | B17: Sigla | C17: Descripcion Operativa | D17: Total Elementos | E17: Puntos PFNA | F17: % del Sistema | G17: Complejidad Predominante
A18: Entradas Externas | B18: EI | C18: Transacciones de altas, bajas y modificaciones en tablas | D18: 39 | E18: ='Consolidado PFNA'!C18 | F18: =E18/'Consolidado PFNA'!H18 | G18: Bajo - Medio (3-4 PF)
A19: Salidas Externas | B19: EO | C19: Informes y reportes con calculos derivados y formulas | D19: 16 | E19: ='Consolidado PFNA'!D18 | F19: =E19/'Consolidado PFNA'!H18 | G19: Medio (5 PF)
A20: Peticiones / Consultas | B20: EQ | C20: Consultas directas sin calculos derivados y filtros | D20: 19 | E20: ='Consolidado PFNA'!E18 | F20: =E20/'Consolidado PFNA'!H18 | G20: Bajo - Medio (3-4 PF)
A21: Archivos Logicos Internos | B21: ILF | C21: Las 13 tablas relacionales mantenidas por el sistema | D21: 13 | E21: ='Consolidado PFNA'!F18 | F21: =E21/'Consolidado PFNA'!H18 | G21: Bajo (7 PF)
A22: Archivos de Interfaz Externa | B22: EIF | C22: Servicios externos (Stripe, WhatsApp, SAT, CDN, FCM) | D22: 13 | E22: ='Consolidado PFNA'!G18 | F22: =E22/'Consolidado PFNA'!H18 | G22: Bajo (5 PF)
A23: TOTAL GENERAL DE COMPONENTES FUNCIONALES (PFNA): | D23: =SUM(D18:D22) | E23: =SUM(E18:E22) | F23: =SUM(F18:F22) | G23: 100% Cobertura de BD

Sheet Matrices de Referencia
A1: MATRICES OFICIALES DE COMPLEJIDAD Y VALORACION (IFPUG / ALBRECHT)
A2: Reglas de ponderacion y tablas de referencia estandarizadas de 'PuntosDeFuncion.DOC'
A4: 1. DEFINICIONES OPERATIVAS DEL MODELO
A5: Entrada (EI) | B5: Transacciones elementales relacionadas con agregar (altas), eliminar (bajas fisicas o logicas) y modificar datos en las tablas.
A6: Salida (EO) | B6: Consultas o generacion de informes que involucran calculos derivados (como aquellos matematicos, totales prorrateados, balances).
A7: Peticion (EQ) | B7: Consultas directas o generacion de reportes sin calculos matematicos derivados (como listados de catalogos y busquedas).
A8: Archivos Internos (ILF) | B8: Archivos logicos o tablas que son mantenidos y alterados directamente por el propio sistema (usuarios, productos, pedidos...).
A9: Archivos Externos (EIF) | B9: Archivos referenciados solo para consulta por el sistema pero mantenidos por sistemas externos (Stripe, WhatsApp, SAT...).
A11: TABLA 1. MATRIZ DE COMPLEJIDAD PARA ENTRADAS EXTERNAS (EI)
A12: Archivos Referenciados (FTR) | B12: 1 - 4 Elementos (DET) | C12: 5 - 15 Elementos (DET) | D12: 16 o mas Elementos (DET)
A13: Menos de 2 (< 2 FTR) | B13: Bajo | C13: Bajo | D13: Medio
A14: 2 FTR | B14: Bajo | C14: Medio | D14: Alto
A15: Mas de 2 (> 2 FTR) | B15: Medio | C15: Alto | D15: Alto
A17: TABLA 2. MATRIZ DE COMPLEJIDAD PARA SALIDAS (EO) Y PETICIONES (EQ)
A18: Archivos Referenciados (FTR) | B18: 1 - 5 Elementos (DET) | C18: 6 - 19 Elementos (DET) | D18: 20 o mas Elementos (DET)
A19: Menos que 2 (< 2 FTR) | B19: Bajo | C19: Bajo | D19: Medio
A20: 2 - 3 FTR | B20: Bajo | C20: Medio | D20: Alto
A21: Mas de 3 (> 3 FTR) | B21: Medio | C21: Alto | D21: Alto
A23: TABLA 3. MATRIZ DE COMPLEJIDAD PARA ARCHIVOS INTERNOS (ILF) Y EXTERNOS (EIF)
A24: Tipos de Registro (RET) | B24: 1 - 19 Elementos (DET) | C24: 20 - 50 Elementos (DET) | D24: 51 o mas Elementos (DET)
A25: Menos de 2 (1 RET) | B25: Bajo | C25: Bajo | D25: Medio
A26: 2 - 5 RET | B26: Bajo | C26: Medio | D26: Alto
A27: Mas de 5 (> 5 RET) | B27: Medio | C27: Alto | D27: Alto
A29: TABLA 4. TABLA DE PONDERACION OFICIAL DE PUNTOS DE FUNCION NO AJUSTADOS
A30: Componente Funcional | B30: Bajo | C30: Medio | D30: Alto
A31: Entradas Externas (EI) | B31: 3 | C31: 4 | D31: 6
A32: Salidas Externas (EO) | B32: 4 | C32: 5 | D32: 7
A33: Peticiones / Consultas (EQ) | B33: 3 | C33: 4 | D33: 6
A34: Archivos Logicos Internos (ILF) | B34: 7 | C34: 10 | D34: 15
A35: Archivos de Interfaz Externa (EIF) | B35: 5 | C35: 7 | D35: 10
A37: 5. ESCALA DE GRADOS DE INFLUENCIA DE ALBRECHT (0 A 5)
A38: Nivel | B38: Significado | C38: Criterio de Evaluacion
A39: 0 | B39: Sin influencia | C39: La caracteristica no esta presente en el sistema o no influye en absoluto.
A40: 1 | B40: Incidental | C40: La caracteristica tiene una influencia minima en el desarrollo del sistema.
A41: 2 | B41: Moderado | C41: La caracteristica tiene una influencia menor o moderada en el diseno.
A42: 3 | B42: Medio | C42: La caracteristica tiene una influencia tipica o promedio en la aplicacion.
A43: 4 | B43: Significativo | C43: La caracteristica es un requerimiento fuerte y clave en el sistema.
A44: 5 | B44: Esencial | C44: La caracteristica es critica e indispensable; el sistema no funciona sin ella.

Sheet Desglose por Tabla (13 Tablas)
A1: DESGLOSE COMPLETO DE PUNTOS DE FUNCION NO AJUSTADOS (PFNA) - 13 TABLAS BD
A2: Especificacion individual de las 5 Tablas del documento de referencia por cada entidad de la BD LocalMarket
A4: TABLA 1: USUARIOS (CUENTAS, PERFILES Y AUTENTICACION)
A5: Tabla 1. Entradas (EI) - Tabla: usuarios
A6: Num. | B6: Entrada / Transaccion | C6: Archivos referidos (FTR) | D6: Elementos de datos (DET) | E6: Nivel | F6: Valor
A7: 1 | B7: Registro de Nuevo Usuario (Alta en Plataforma) | C7: 2 (usuarios, roles) | D7: 9 (id_rol, nombre, correo, pass, tel...) | E7: Medio | F7: 4
A8: 2 | B8: Actualizacion de Perfil de Usuario (Modificacion) | C8: 1 (usuarios) | D8: 6 (nombre, telefono, foto, correo...) | E8: Bajo | F8: 3
A9: 3 | B9: Baja / Suspension de Cuenta de Usuario | C9: 2 (usuarios, control_suspensiones) | D9: 2 (id_usuario, estado_cuenta) | E9: Bajo | F9: 3
A10: Subtotal EI (usuarios): | F10: =SUM(F7:F9)
A11: Tabla 2. Salidas (EO) - Tabla: usuarios
A12: Num. | B12: Salida (Reporte con Calculos) | C12: Archivos referidos (FTR) | D12: Elementos de datos (DET) | E12: Nivel | F12: Valor
A13: 1 | B13: Reporte de Actividad y Comisiones por Usuario (Calculo de ventas brutas, retenciones y saldo neto) | C13: 3 (usuarios, pedidos, detalle_pedidos) | D13: 8 (id_usuario, nombre, total_ventas, comision_pct, saldo_favor...) | E13: Medio | F13: 5
A14: 2 | B14: Resumen Financiero y Balance de Credito en Plataforma (Calculo de compras totales y limite) | C14: 2 (usuarios, pedidos) | D14: 6 (id_usuario, total_compras, saldo_disponible, credito_usado...) | E14: Medio | F14: 5
A15: Subtotal EO (usuarios): | F15: =SUM(F13:F14)
A16: Tabla 3. Peticiones (EQ) - Tabla: usuarios
A17: Num. | B17: Peticion (Consulta Directa) | C17: Archivos referidos (FTR) | D17: Elementos de datos (DET) | E17: Nivel | F17: Valor
A18: 1 | B18: Consulta de Usuario por ID / Correo (Autenticacion y login) | C18: 2 (usuarios, roles) | D18: 6 (id_usuario, nombre, correo, nombre_rol, estado...) | E18: Medio | F18: 4
A19: 2 | B19: Listado de Usuarios Registrados en Panel de Control | C19: 2 (usuarios, roles) | D19: 5 (id_usuario, nombre, correo, telefono, rol) | E19: Bajo | F19: 3
A20: Subtotal EQ (usuarios): | F20: =SUM(F18:F19)
A21: Tabla 4. Archivos Internos (ILF) - Tabla: usuarios
A22: Num. | B22: Archivo / Tabla Interna | C22: Elementos de registro (RET) | D22: Elementos de datos (DET) | E22: Nivel | F22: Valor
A23: 1 | B23: Tabla: usuarios (Entidad maestra de cuentas, seguridad y perfiles) | C23: 1 (Registro Usuario) | D23: 10 (id_usuario, id_rol, nombre, correo, contrasena, tel, foto, otp, estado, fecha) | E23: Bajo | F23: 7
A24: Subtotal ILF (usuarios): | F24: =SUM(F23:F23)
A25: Tabla 5. Archivos Externos (EIF) - Tabla: usuarios
A26: Num. | B26: Archivo / Interfaz Externa | C26: Elementos de registro (RET) | D26: Elementos de datos (DET) | E26: Nivel | F26: Valor
A27: 1 | B27: Servicio Externo de Validacion de Identidad y SMS (Twilio / Carrier API) | C27: 1 (Registro de Telefono) | D27: 4 (telefono, country_code, carrier_status, valid) | E27: Bajo | F27: 5
A28: Subtotal EIF (usuarios): | F28: =SUM(F27:F27)
A29: TOTAL PUNTOS DE FUNCION TABLA 1: USUARIOS: | F29: =F10+F15+F20+F24+F28
A31: TABLA 2: ROLES (CONTROL DE ACCESO BASADO EN ROLES - RBAC)
A32: Tabla 1. Entradas (EI) - Tabla: roles
A33: Num. | B33: Entrada / Transaccion | C33: Archivos referidos (FTR) | D33: Elementos de datos (DET) | E33: Nivel | F33: Valor
A34: 1 | B34: Crear Nuevo Rol de Sistema (Alta) | C34: 1 (roles) | D34: 3 (id_rol, nombre_rol, descripcion) | E34: Bajo | F34: 3
A35: 2 | B35: Modificar Privilegios de Rol (Edicion) | C35: 2 (roles, roles_permisos) | D35: 3 (nombre_rol, descripcion, permisos) | E35: Bajo | F35: 3
A36: 3 | B36: Desactivar / Eliminar Rol no Asignado (Baja) | C36: 2 (roles, usuarios) | D36: 1 (id_rol) | E36: Bajo | F36: 3
A37: Subtotal EI (roles): | F37: =SUM(F34:F36)
A38: Tabla 2. Salidas (EO) - Tabla: roles
A39: Num. | B39: Salida (Reporte con Calculos) | C39: Archivos referidos (FTR) | D39: Elementos de datos (DET) | E39: Nivel | F39: Valor
A40: 1 | B40: Matriz de Cobertura y Auditoria de Permisos RBAC (Calculo porcentual de cobertura de modulos) | C40: 2 (roles, roles_permisos) | D40: 6 (nombre_rol, total_permisos, permisos_activos, cobertura_pct...) | E40: Medio | F40: 5
A41: Subtotal EO (roles): | F41: =SUM(F40:F40)
A42: Tabla 3. Peticiones (EQ) - Tabla: roles
...

Sheet Consolidado PFNA
A1: MATRIZ CONSOLIDADA DE PUNTOS DE FUNCION NO AJUSTADOS (PFNA) - 13 TABLAS
A2: Resumen ejecutivo por componente funcional (EI, EO, EQ, ILF, EIF) y peso porcentual de cada tabla
A4: Num. | B4: Tabla de Base de Datos | C4: Entradas (EI) | D4: Salidas (EO) | E4: Peticiones (EQ) | F4: Archivos Int. (ILF) | G4: Archivos Ext. (EIF) | H4: Total PFNA Tabla | I4: % Participacion
A5: 1 | B5: Tabla: usuarios | C5: ='Desglose por Tabla (13 Tablas)'!F10 | D5: ='Desglose por Tabla (13 Tablas)'!F15 | E5: ='Desglose por Tabla (13 Tablas)'!F20 | F5: ='Desglose por Tabla (13 Tablas)'!F24 | G5: ='Desglose por Tabla (13 Tablas)'!F28 | H5: =SUM(C5:G5) | I5: =H5/H18
A6: 2 | B6: Tabla: roles | C6: ='Desglose por Tabla (13 Tablas)'!F37 | D6: ='Desglose por Tabla (13 Tablas)'!F41 | E6: ='Desglose por Tabla (13 Tablas)'!F46 | F6: ='Desglose por Tabla (13 Tablas)'!F50 | G6: ='Desglose por Tabla (13 Tablas)'!F54 | H6: =SUM(C6:G6) | I6: =H6/H18
A7: 3 | B7: Tabla: verificaciones_otp | C7: ='Desglose por Tabla (13 Tablas)'!F63 | D7: ='Desglose por Tabla (13 Tablas)'!F67 | E7: ='Desglose por Tabla (13 Tablas)'!F71 | F7: ='Desglose por Tabla (13 Tablas)'!F75 | G7: ='Desglose por Tabla (13 Tablas)'!F79 | H7: =SUM(C7:G7) | I7: =H7/H18
A8: 4 | B8: Tabla: categorias | C8: ='Desglose por Tabla (13 Tablas)'!F88 | D8: ='Desglose por Tabla (13 Tablas)'!F92 | E8: ='Desglose por Tabla (13 Tablas)'!F97 | F8: ='Desglose por Tabla (13 Tablas)'!F101 | G8: ='Desglose por Tabla (13 Tablas)'!F105 | H8: =SUM(C8:G8) | I8: =H8/H18
A9: 5 | B9: Tabla: productos | C9: ='Desglose por Tabla (13 Tablas)'!F114 | D9: ='Desglose por Tabla (13 Tablas)'!F119 | E9: ='Desglose por Tabla (13 Tablas)'!F124 | F9: ='Desglose por Tabla (13 Tablas)'!F128 | G9: ='Desglose por Tabla (13 Tablas)'!F132 | H9: =SUM(C9:G9) | I9: =H9/H18
A10: 6 | B10: Tabla: imagenes_producto | C10: ='Desglose por Tabla (13 Tablas)'!F141 | D10: ='Desglose por Tabla (13 Tablas)'!F145 | E10: ='Desglose por Tabla (13 Tablas)'!F149 | F10: ='Desglose por Tabla (13 Tablas)'!F153 | G10: ='Desglose por Tabla (13 Tablas)'!F157 | H10: =SUM(C10:G10) | I10: =H10/H18
A11: 7 | B11: Tabla: carrito | C11: ='Desglose por Tabla (13 Tablas)'!F166 | D11: ='Desglose por Tabla (13 Tablas)'!F170 | E11: ='Desglose por Tabla (13 Tablas)'!F174 | F11: ='Desglose por Tabla (13 Tablas)'!F178 | G11: ='Desglose por Tabla (13 Tablas)'!F182 | H11: =SUM(C11:G11) | I11: =H11/H18
A12: 8 | B12: Tabla: detalle_carrito | C12: ='Desglose por Tabla (13 Tablas)'!F191 | D12: ='Desglose por Tabla (13 Tablas)'!F195 | E12: ='Desglose por Tabla (13 Tablas)'!F199 | F12: ='Desglose por Tabla (13 Tablas)'!F203 | G12: ='Desglose por Tabla (13 Tablas)'!F207 | H12: =SUM(C12:G12) | I12: =H12/H18
A13: 9 | B13: Tabla: pedidos | C13: ='Desglose por Tabla (13 Tablas)'!F216 | D13: ='Desglose por Tabla (13 Tablas)'!F221 | E13: ='Desglose por Tabla (13 Tablas)'!F226 | F13: ='Desglose por Tabla (13 Tablas)'!F230 | G13: ='Desglose por Tabla (13 Tablas)'!F234 | H13: =SUM(C13:G13) | I13: =H13/H18
A14: 10 | B14: Tabla: detalle_pedidos | C14: ='Desglose por Tabla (13 Tablas)'!F243 | D14: ='Desglose por Tabla (13 Tablas)'!F247 | E14: ='Desglose por Tabla (13 Tablas)'!F251 | F14: ='Desglose por Tabla (13 Tablas)'!F255 | G14: ='Desglose por Tabla (13 Tablas)'!F259 | H14: =SUM(C14:G14) | I14: =H14/H18
A15: 11 | B15: Tabla: notificaciones | C15: ='Desglose por Tabla (13 Tablas)'!F268 | D15: ='Desglose por Tabla (13 Tablas)'!F272 | E15: ='Desglose por Tabla (13 Tablas)'!F276 | F15: ='Desglose por Tabla (13 Tablas)'!F280 | G15: ='Desglose por Tabla (13 Tablas)'!F284 | H15: =SUM(C15:G15) | I15: =H15/H18
A16: 12 | B16: Tabla: bitacora_seguridad | C16: ='Desglose por Tabla (13 Tablas)'!F293 | D16: ='Desglose por Tabla (13 Tablas)'!F297 | E16: ='Desglose por Tabla (13 Tablas)'!F301 | F16: ='Desglose por Tabla (13 Tablas)'!F305 | G16: ='Desglose por Tabla (13 Tablas)'!F309 | H16: =SUM(C16:G16) | I16: =H16/H18
A17: 13 | B17: Tabla: control_suspensiones | C17: ='Desglose por Tabla (13 Tablas)'!F318 | D17: ='Desglose por Tabla (13 Tablas)'!F322 | E17: ='Desglose por Tabla (13 Tablas)'!F327 | F17: ='Desglose por Tabla (13 Tablas)'!F331 | G17: ='Desglose por Tabla (13 Tablas)'!F335 | H17: =SUM(C17:G17) | I17: =H17/H18
A18: TOTALES GENERALES CONSOLIDADOS (PFNA): | C18: =SUM(C5:C17) | D18: =SUM(D5:D17) | E18: =SUM(E5:E17) | F18: =SUM(F5:F17) | G18: =SUM(G5:G17) | H18: =SUM(H5:H17) | I18: =SUM(I5:I17)

Sheet PF Ajustados
A1: CALCULO DE PUNTOS DE FUNCION AJUSTADOS (PFA) - MODELO DE ALBRECHT
A2: Evaluacion de los 14 Factores de Ajuste (GSC) | Formula Oficial: PFA = PFNA * [ 0.65 + 0.01 * SUMA(Fi) ]
A4: Num. | B4: Caracteristica General del Sistema (GSC / Albrecht) | C4: Nivel de Influencia (0 - 5) | D4: Puntaje (Fi) | E4: Justificacion Tecnica Exhaustiva en LocalMarket
A5: F1 | B5: 1. Comunicacion de datos | C5: 4 - Significativo | D5: 4 | E5: Arquitectura cliente-servidor PWA con endpoints REST HTTPS, WebSockets para notificaciones y APIs externas (WhatsApp, Stripe).
A6: F2 | B6: 2. Procesamiento distribuido | C6: 3 - Moderado | D6: 3 | E6: Procesamiento distribuido entre cliente (Service Workers, renderizado dinamico en dashboard.js) y servidor Node.js/PostgreSQL.
A7: F3 | B7: 3. Rendimiento y performance | C7: 4 - Significativo | D7: 4 | E7: Tiempos de respuesta criticos en catalogo comercial, sincronizacion offline PWA y confirmacion de compras en tiempo real.
A8: F4 | B8: 4. Configuracion del equipamiento fuertemente utilizada | C8: 3 - Moderado | D8: 3 | E8: Operacion continua en entorno Node.js / PostgreSQL con optimizacion de pool de conexiones (pg.Pool) y gestion de memoria.
A9: F5 | B9: 5. Volumen de transacciones | C9: 4 - Significativo | D9: 4 | E9: Picos intensivos de transacciones comerciales concurrentes durante horarios comerciales, liquidacion de carritos y consultas.
A10: F6 | B10: 6. Entrada de datos interactiva en linea | C10: 5 - Esencial | D10: 5 | E10: El 100% de las operaciones de registro, gestion de catalogo, cotizacion, pago y moderacion se ejecuta interactivamente.
A11: F7 | B11: 7. Eficiencia del usuario final (Multiples pantallas) | C11: 4 - Significativo | D11: 4 | E11: Panel de control multifuncional desacoplado con pestanas dinamicas (Auth, Catalogo, Pedidos, Notificaciones, Bitacora, Control).
A12: F8 | B12: 8. Actualizacion interactiva de archivos maestros | C12: 4 - Significativo | D12: 4 | E12: Las tablas maestras (usuarios, productos, pedidos, stock) se actualizan en tiempo real con transacciones ACID en PostgreSQL.
A13: F9 | B13: 9. Complejidad logica de transacciones / procesamiento | C13: 4 - Significativo | D13: 4 | E13: Logica compleja de control de acceso RBAC, verificacion OTP con temporizador, calculo de comisiones y politicas de suspension.
A14: F10 | B14: 10. Complejidad del procesamiento interno | C14: 3 - Moderado | D14: 3 | E14: Calculo de margenes brutos, prorrateo de envios, conciliacion contable de ventas y algoritmos criptograficos (bcrypt, tokens).
A15: F11 | B15: 11. Reusabilidad del codigo | C15: 4 - Significativo | D15: 4 | E15: Arquitectura modular profesional en Express (controllers, routes, middlewares RBAC) y componentes JS desacoplados y reusables.
A16: F12 | B16: 12. Facilidad de instalacion y conversion | C16: 4 - Significativo | D16: 4 | E16: Estructura lista con npm start, migraciones SQL DDL/DML automatizadas y compatibilidad PWA instalable con 1 clic en movil/PC.
... A18: F14 | B18: 14. Facilidad de cambios y mantenimiento | C18: 4 - Significativo | D18: 4 | E18: Codigo estructurado y comentado, variables de entorno desacopladas (.env), alta cohesion y bajo acoplamiento arquitectonico.
A19: SUMATORIA TOTAL DE FACTORES GENERALES DE COMPLEJIDAD (SUMA(Fi)): | D19: =SUM(D5:D18) | E19: Rango teorico: 0 a 70 puntos maximos
A22: CUADRO RESUMEN DE CALCULO DE PUNTOS DE FUNCION AJUSTADOS (PFA)
A23: Parametro / Metrica | B23: Valor | C23: Formula de Calculo | D23: Descripcion e Interpretacion Tecnica
A24: Total PF No Ajustados (PFNA) | B24: ='Consolidado PFNA'!H18 | C24: ='Consolidado PFNA'!H18 | D24: Tamano funcional elemental no ajustado de las 13 tablas de la base de datos.
A25: Suma Factores de Complejidad (SUMA(Fi)) | B25: =D19 | C25: =SUM(D5:D18) | D25: Grado de influencia acumulado de las 14 caracteristicas generales del sistema.
A26: Factor de Ajuste de Complejidad (CAF) | B26: =0.65+(0.01*B25) | C26: =0.65 + 0.01 * B25 | D26: Factor multiplicador (CAF) entre 0.65 y 1.35 segun el estandar de Albrecht.
A27: TOTAL PUNTOS DE FUNCION AJUSTADOS (PFA) | B27: =B24*B26 | C27: =B24 * B26 | D27: Tamano de software definitivo ajustado por complejidad para estimacion de esfuerzo y costos.
A30: ESTIMACIONES DERIVADAS DE INGENIERIA DE SOFTWARE (BENCHMARKS COCOMO / QSM)
A31: Metrica Derivada | B31: Valor Estimado | C31: Unidad | D31: Base de Referencia y Metodologia
A32: Lineas de Codigo Fuente (KLOC) Equivalentes | B32: =B27*53 | C32: LOC (Lineas) | D32: Factor de conversion de 53 LOC/PF para JavaScript / Node.js y SQL (QSM).
A33: Esfuerzo de Desarrollo Estimado (Horas-Hombre) | B33: =B27*8 | C33: Horas-Hombre | D33: Tasa de productividad promedio de la industria de 8 horas por Punto de Funcion.
A34: Esfuerzo de Desarrollo en Meses-Hombre | B34: =(B27*8)/160 | C34: Meses-Hombre | D34: Jornada laboral de 160 horas efectivas de desarrollo al mes.
A35: Duracion Estimada del Proyecto (Meses) | B35: =2.5*((B27*8)/160)^0.33 | C35: Meses Calendario | D35: Ecuacion de duracion de COCOMO II con equipo optimo de 3 a 4 ingenieros.
A36: Tamano del Equipo Recomendado | B36: =((B27*8)/160)/(2.5*((B27*8)/160)^0.33) | C36: Desarrolladores | D36: Ratio entre Meses-Hombre totales y duracion optima del calendario.
